Workbook
Name IQ_CH: 110000
Name IQ_CQ: 5000
Name IQ_CY: 10000
Name IQ_DAILY: 500000
Name IQ_FH: 100000
Name IQ_FQ: 500
Name IQ_FY: 1000
Name IQ_LTM: 2000
Name IQ_MONTH: 15000
Name IQ_NTM: 6000
Name IQ_WEEK: 50000
Name IQ_YTD: 3000

Sheet Valuation Summary
C2: Tullow Oil Valuation Summary
C4: Valuation Summary
C5: Intrinsic Valuation | K5: Low | L5: Med | M5: High
C6: Liquidation Valuation | K6: ='Liquidation Value'!L47 -> 633.48 | L6: ='Liquidation Value'!M47 -> 1305.01 | M6: ='Liquidation Value'!N47 -> 1431.9555
C7: Discounted Cash Flow Valuation | K7: =DCF!T25 -> 2288.2377 | L7: =DCF!U25 -> 2535.6915 | M7: =DCF!V25 -> 2809.9751
C9: Relative Valuation | K9: Low (25th) | L9: Med (Median) | M9: High (75th)
C10: Trading Comps Valuation (EV/EBITDA) | K10: ='Trading Comps'!E18*'Trading Comps'!R6 -> 2433.4561 | L10: ='Trading Comps'!E19*'Trading Comps'!R6 -> 3910.4795 | M10: ='Trading Comps'!E21*'Trading Comps'!R6 -> 5051.0746
C11: Precedent Transactions (EV/EBITDA) | K11: ='Precedent Transactions '!G20*'Precedent Transactions '!$N$8 -> 1232.8133 | L11: ='Precedent Transactions '!G21*'Precedent Transactions '!N8 -> 1510.1717 | M11: ='Precedent Transactions '!G23*'Precedent Transactions '!N8 -> 2592.4637
C13: Indicated Enterprise Value Range | K13: =MIN(MIN(K6:M7),MIN(K10:M11)) -> 633.48 | L13: to | M13: =MAX(MAX(K6:M7),MAX(K10:M11)) -> 5051.0746
C15: Trading Comps Valuation
C17: Relevant Financial Measures | G17: Selected Multiples | K17: Indicated Enterprise Value
C19: EBITDA (2024E): | G19: Low | H19: Med | I19: High | K19: Low | L19: Med | M19: High
C20: Adjusted EBITDA | E20: ='Trading Comps'!$R$6 -> 666.9 | G20: ='Trading Comps'!E18 -> 3.648907 | H20: ='Trading Comps'!E19 -> 5.863667 | I20: ='Trading Comps'!E21 -> 7.573961 | K20: =$E20*G20 -> 2433.4561 | L20: =$E20*H20 -> 3910.4795 | M20: =$E20*I20 -> 5051.0746
C22: Precedent Transaction Valuation
C24: Relevant Financial Measures | G24: Selected Multiples | K24: Indicated Enterprise Value
C26: EBITDA (2024E): | G26: Low | H26: Med | I26: High | K26: Low | L26: Med | M26: High
C27: Adjusted EBITDA | E27: ='Trading Comps'!$R$6 -> 666.9 | G27: ='Precedent Transactions '!G20 -> 1.848573 | H27: ='Precedent Transactions '!G21 -> 2.2644651 | I27: ='Precedent Transactions '!G23 -> 3.8873349 | K27: =$E27*G27 -> 1232.8133 | L27: =$E27*H27 -> 1510.1717 | M27: =$E27*I27 -> 2592.4637
C29: Discounted Cash Flow Valuation
C31: Relevant Financial Measures | G31: Selected WACC | K31: Indicated Enterprise Value
C33: EBITDA (2024E): | G33: Low | H33: Med | I33: High | K33: Low | L33: Med | M33: High
C34: Adjusted EBITDA | E34: ='Trading Comps'!$R$6 -> 666.9 | G34: =DCF!J37 -> 0.24412793 | H34: =DCF!K37 -> 0.20779362 | I34: =DCF!L37 -> 0.1714593 | K34: =DCF!T25 -> 2288.2377 | L34: =DCF!U25 -> 2535.6915 | M34: =DCF!V25 -> 2809.9751
C36: Liquidation Valuation
C38: Relevant Financial Measures | G38: Avg. Asset Recovery Values | K38: Indicated Enterprise Value
C40: Pre-Restructuring Balance Sheet | G40: Low | H40: Med | I40: High | K40: Low | L40: Med | M40: High
C41: Total Assets | E41: =+'Liquidation Value'!F19 -> 3872.1 | G41: =AVERAGE('Liquidation Value'!H9:H18) -> 0.395 | H41: =AVERAGE('Liquidation Value'!I9:I18) -> 0.585 | I41: =AVERAGE('Liquidation Value'!J9:J18) -> 0.775 | K41: ='Liquidation Value'!L47 -> 633.48 | L41: ='Liquidation Value'!M47 -> 1305.01 | M41: ='Liquidation Value'!N47 -> 1431.9555
C43: Football Field Valuation Range
C44: Valuation | D44: Low (bar) | E44: Lo (Label) | F44: High (Bar) | G44: High (Label)
C45: Liquidation Valuation | D45: =MIN($K$41:$M$41) -> 633.48 | E45: =D45 -> 633.48 | F45: =MAX($K$41:$M$41) -> 1431.9555 | G45: =F45 -> 1431.9555
C46: Discounted Cash Flow | D46: =MIN($K$34:$M$34) -> 2288.2377 | E46: =D46 -> 2288.2377 | F46: =MAX($K$34:$M$34) -> 2809.9751 | G46: =F46 -> 2809.9751
C47: Precedent Transactions | D47: =MIN($K$27:$M$27) -> 1232.8133 | E47: =D47 -> 1232.8133 | F47: =MAX($K$27:$M$27) -> 2592.4637 | G47: =F47 -> 2592.4637
C48: Trading Comps | D48: =MIN($K$20:$M$20) -> 2433.4561 | E48: =D48 -> 2433.4561 | F48: =MAX($K$20:$M$20) -> 5051.0746 | G48: =F48 -> 5051.0746

Sheet IS
D1: 2019 | E1: =D1+1 -> 2020 | F1: =E1+1 -> 2021 | G1: =F1+1 -> 2022 | H1: =G1+1 -> 2023 | I1: =H1+1 -> 2024 | J1: =I1+1 -> 2025 | K1: =J1+1 -> 2026 | L1: =K1+1 -> 2027 | ... Q1: =P1+1 -> 2032
C2: Tullow Oil Income Statement
C4: Income Statement
C5: Revenue | D5: 1682.6 | E5: 1396.1 | F5: 1285.4 | G5: 1783.1 | H5: 1634.1 | I5: 1534.9 | J5: ='Revenue Build'!J5 -> 1145.735 | K5: ='Revenue Build'!K5 -> 996.45 | L5: ='Revenue Build'!L5 -> 1003.6441 | M5: ='Revenue Build'!M5 -> 986.084 | N5: ='Revenue Build'!N5 -> 967.85955 | O5: ='Revenue Build'!O5 -> 948.9708 | P5: ='Revenue Build'!P5 -> 917.829 | Q5: ='Revenue Build'!Q5 -> 885.7674
C6: YOY Growth | D6: 0 | E6: =(E5-D5)/D5 -> -0.1702722 | F6: =(F5-E5)/E5 -> -0.079292314 | G6: =(G5-F5)/F5 -> 0.38719465 | H6: =(H5-G5)/G5 -> -0.083562335 | I6: =(I5-H5)/H5 -> -0.060706199 | J6: =(J5-I5)/I5 -> -0.2535442 | K6: =(K5-J5)/J5 -> -0.13029627 | L6: =(L5-K5)/K5 -> 0.0072197802 | ... Q6: =(Q5-P5)/P5 -> -0.034931997
C8: Cost Of Goods Sold | D8: -970.9 | E8: -993.6 | F8: -631 | G8: -682.8 | H8: -843.3 | I8: -772.6 | J8: =-J$5*J63 -> -607.61498 | K8: =-K$5*K63 -> -528.44501 | L8: =-L$5*L63 -> -532.26027 | M8: =-M$5*M63 -> -522.94764 | N8: =-N$5*N63 -> -513.28271 | O8: =-O$5*O63 -> -503.26548 | P8: =-P$5*P63 -> -486.75012 | Q8: =-Q$5*Q63 -> -469.74697
C9: Gross Profit | D9: =D5+D8 -> 711.7 | E9: =E5+E8 -> 402.5 | F9: =F5+F8 -> 654.4 | G9: =G5+G8 -> 1100.3 | H9: =H5+H8 -> 790.8 | I9: =I5+I8 -> 762.3 | J9: =J5+J8 -> 538.12002 | K9: =K5+K8 -> 468.00499 | ... Q9: =Q5+Q8 -> 416.02043
C10: Gross Margin | D10: =D9/D$5 -> 0.42297635 | E10: =E9/E$5 -> 0.28830313 | F10: =F9/F$5 -> 0.50910222 | G10: =G9/G$5 -> 0.61707139 | H10: =H9/H$5 -> 0.48393611 | I10: =I9/I$5 -> 0.49664473 | J10: =J9/J$5 -> 0.46967232 | K10: =K9/K$5 -> 0.46967232 | ... Q10: =Q9/Q$5 -> 0.46967232
C12: Selling General & Admin Exp. | D12: -111.5 | E12: -86.7 | F12: -64.1 | G12: -51 | H12: -56.1 | I12: -53.2 | J12: =-J$5*J66 -> -52.671107 | K12: =-K$5*K66 -> -45.808258 | L12: =-L$5*L66 -> -46.138984 | M12: =-M$5*M66 -> -45.331718 | N12: =-N$5*N66 -> -44.493914 | O12: =-O$5*O66 -> -43.62557 | P12: =-P$5*P66 -> -42.193936 | Q12: =-Q$5*Q66 -> -40.720018
C13: Provision for Bad Debts | D13: 0 | E13: 0 | F13: 0 | G13: 0 | H13: 0 | I13: -6.6 | J13: 0 | K13: =J13 -> 0 | L13: =K13 -> 0 | M13: =L13 -> 0 | N13: =M13 -> 0 | O13: =N13 -> 0 | P13: =O13 -> 0 | Q13: =P13 -> 0
C14: Impair. of Oil, Gas & Mineral Prop. | D14: 0 | E14: 0 | F14: -114.2 | G14: -496.4 | H14: -27 | I14: -212.6 | J14: =-J71 -> -155.32415 | K14: =J14 -> -155.32415 | L14: =K14 -> -155.32415 | M14: =L14 -> -155.32415 | N14: =M14 -> -155.32415 | O14: =N14 -> -155.32415 | P14: =O14 -> -155.32415 | Q14: =P14 -> -155.32415
C15: Other Operating Expense/(Income) | D15: -17.8 | E15: -38.9 | F15: -7.6 | G15: -7 | H15: 12.1 | I15: 59 | J15: =J74 -> -44.040892 | K15: =J15 -> -44.040892 | L15: =K15 -> -44.040892 | M15: =L15 -> -44.040892 | N15: =M15 -> -44.040892 | O15: =N15 -> -44.040892 | P15: =O15 -> -44.040892 | Q15: =P15 -> -44.040892
C17: Other Operating Expenses | D17: =SUM(D12:D15) -> -129.3 | E17: =SUM(E12:E15) -> -125.6 | F17: =SUM(F12:F15) -> -185.9 | G17: =SUM(G12:G15) -> -554.4 | H17: =SUM(H12:H15) -> -71 | I17: =SUM(I12:I15) -> -213.4 | J17: =SUM(J12:J15) -> -252.03615 | K17: =SUM(K12:K15) -> -245.1733 | ... Q17: =SUM(Q12:Q15) -> -240.08506
C18: Operating Income | D18: =D9+D17 -> 582.4 | E18: =E9+E17 -> 276.9 | F18: =F9+F17 -> 468.5 | G18: =G9+G17 -> 545.9 | H18: =H9+H17 -> 719.8 | I18: =I9+I17 -> 548.9 | J18: =J9+J17 -> 286.08387 | K18: =K9+K17 -> 222.83169 | ... Q18: =Q9+Q17 -> 175.93538
C19: Operating Margin | D19: =D18/D$5 -> 0.34613099 | E19: =E18/E$5 -> 0.19833823 | F19: =F18/F$5 -> 0.36447798 | G19: =G18/G$5 -> 0.30615221 | H19: =H18/H$5 -> 0.44048712 | I19: =I18/I$5 -> 0.35761287 | J19: =J18/J$5 -> 0.24969463 | K19: =K18/K$5 -> 0.22362556 | ... Q19: =Q18/Q$5 -> 0.1986248
C21: Interest Expense | D21: -305.3 | E21: -300.4 | F21: -329.4 | G21: -329.2 | H21: -317.6 | I21: -331.2 | J21: =-'Debt Schedule'!J54 -> -204.87245 | K21: =-'Debt Schedule'!K54 -> -129.59312 | L21: =-'Debt Schedule'!L54 -> -95.73 | M21: =-'Debt Schedule'!M54 -> -82.966 | N21: =-'Debt Schedule'!N54 -> -70.202 | O21: =-'Debt Schedule'!O54 -> -57.438 | P21: =-'Debt Schedule'!P54 -> -44.674 | Q21: =-'Debt Schedule'!Q54 -> -19.146
C22: Interest and Invest. Income | D22: 50 | E22: 40.6 | F22: 38.8 | G22: 29.6 | H22: 30.1 | I22: 48.1 | J22: =I22 -> 48.1 | K22: =J22 -> 48.1 | L22: =K22 -> 48.1 | M22: =L22 -> 48.1 | N22: =M22 -> 48.1 | O22: =N22 -> 48.1 | P22: =O22 -> 48.1 | Q22: =P22 -> 48.1
C23: Net Interest Exp. | D23: =SUM(D21:D22) -> -255.3 | E23: =SUM(E21:E22) -> -259.8 | F23: =SUM(F21:F22) -> -290.6 | G23: =SUM(G21:G22) -> -299.6 | H23: =SUM(H21:H22) -> -287.5 | I23: =SUM(I21:I22) -> -283.1 | J23: =SUM(J21:J22) -> -156.77245 | K23: =SUM(K21:K22) -> -81.493124 | ... Q23: =SUM(Q21:Q22) -> 28.954
C25: Other Non-Operating Inc. (Exp.) | D25: 4.8 | E25: 18 | F25: -13.6 | G25: 13.8 | H25: 11.6 | I25: 20.4 | J25: 0 | K25: 0 | L25: 0 | M25: 0 | N25: 0 | O25: 0 | P25: 0 | Q25: 0
C26: EBT Incl. Unusual Items | D26: =D18+D23+D25 -> 331.9 | E26: =E18+E23+E25 -> 35.1 | F26: =F18+F23+F25 -> 164.3 | G26: =G18+G23+G25 -> 260.1 | H26: =H18+H23+H25 -> 443.9 | I26: =I18+I23+I25 -> 286.2 | J26: =J18+J23+J25 -> 129.31143 | K26: =K18+K23+K25 -> 141.33857 | ... Q26: =Q18+Q23+Q25 -> 204.88938
C28: Restructuring Charges | D28: -4.2 | E28: -67.8 | F28: -3.1 | G28: -0.1 | H28: 0 | I28: -7.1 | J28: =I28 -> -7.1 | K28: =J28 -> -7.1 | L28: =K28 -> -7.1 | M28: =L28 -> -7.1 | N28: =M28 -> -7.1 | O28: =N28 -> -7.1 | P28: =O28 -> -7.1 | Q28: =P28 -> -7.1
C29: Impairment of Goodwill | D29: 0 | E29: 0 | F29: 0 | G29: 0 | H29: 0 | I29: 0 | J29: =I29 -> 0 | K29: =J29 -> 0 | L29: =K29 -> 0 | M29: =L29 -> 0 | N29: =M29 -> 0 | O29: =N29 -> 0 | P29: =O29 -> 0 | Q29: =P29 -> 0
C30: Gain (Loss) On Sale Of Assets | D30: 6.6 | E30: -3.4 | F30: 120.3 | G30: 0 | H30: 0 | I30: 0 | J30: =+'Forecast Assumptions'!D89 -> 142.43333 | K30: =+'Forecast Assumptions'!E89 -> 3.6333333 | L30: =+'Forecast Assumptions'!F89 -> 0 | M30: =+'Forecast Assumptions'!G89 -> 0.72666667 | N30: =+'Forecast Assumptions'!H89 -> 0.72666667 | O30: =+'Forecast Assumptions'!I89 -> 0.72666667 | P30: =+'Forecast Assumptions'!J89 -> 0.72666667 | Q30: =+'Forecast Assumptions'!K89 -> 0.72666667
C31: Asset Write-down | D31: -2034.6 | E31: -1237.3 | F31: 0 | G31: 0 | H31: -408.1 | I31: 50.7 | J31: 0 | K31: =J31 -> 0 | L31: =K31 -> 0 | M31: =L31 -> 0 | N31: =M31 -> 0 | O31: =N31 -> 0 | P31: =O31 -> 0 | Q31: =P31 -> 0
C32: Insurance Settlements | D32: 46.9 | E32: 0 | F32: 0 | G32: 0 | H32: 0 | I32: 0 | J32: =I32 -> 0 | K32: =J32 -> 0 | L32: =K32 -> 0 | M32: =L32 -> 0 | N32: =M32 -> 0 | O32: =N32 -> 0 | P32: =O32 -> 0 | Q32: =P32 -> 0
C33: Other Unusual Items | D33: 0 | E33: 0 | F33: -66.6 | G33: 182.1 | H33: 60.1 | I33: -8.3 | J33: -65.4 | K33: 0 | L33: =K33 -> 0 | M33: =L33 -> 0 | N33: =M33 -> 0 | O33: =N33 -> 0 | P33: =O33 -> 0 | Q33: =P33 -> 0
C34: EBT Excl. Unusual Items | D34: =SUM(D26:D33) -> -1653.4 | E34: =SUM(E26:E33) -> -1273.4 | F34: =SUM(F26:F33) -> 214.9 | G34: =SUM(G26:G33) -> 442.1 | H34: =SUM(H26:H33) -> 95.9 | I34: =SUM(I26:I33) -> 321.5 | J34: =SUM(J28:J33)+J26 -> 199.24476 | K34: =SUM(K28:K33)+K26 -> 137.8719 | L34: =SUM(L28:L33)+L26 -> 171.14986 | M34: =SUM(M28:M33)+M26 -> 177.20027 | N34: =SUM(N28:N33)+N26 -> 182.24256 | O34: =SUM(O28:O33)+O26 -> 187.00338 | P34: =SUM(P28:P33)+P26 -> 186.57257 | Q34: =SUM(Q28:Q33)+Q26 -> 198.51604
C36: Income Tax Expense | D36: -40.7 | E36: 51.9 | F36: -295.6 | G36: -393 | H36: -205.5 | I36: -266.9 | J36: =-J34*J37 -> -119.7461 | K36: =-K34*K37 -> -82.861011 | L36: =-L34*L37 -> -102.86106 | M36: =-M34*M37 -> -106.49736 | N36: =-N34*N37 -> -109.52778 | O36: =-O34*O37 -> -112.38903 | P36: =-P34*P37 -> -112.13011 | Q36: =-Q34*Q37 -> -119.30814
C37: Adj. Effective Tax Rate | D37: 0.716 | E37: 0.356 | F37: 1.17 | G37: 0.703 | H37: 0.702 | I37: 0.601 | J37: =I37 -> 0.601 | K37: =J37 -> 0.601 | L37: =K37 -> 0.601 | M37: =L37 -> 0.601 | N37: =M37 -> 0.601 | O37: =N37 -> 0.601 | P37: =O37 -> 0.601 | Q37: =P37 -> 0.601
C38: Earnings from Cont. Ops. | D38: =D34+D36 -> -1694.1 | E38: =E34+E36 -> -1221.5 | F38: =F34+F36 -> -80.7 | G38: =G34+G36 -> 49.1 | H38: =H34+H36 -> -109.6 | I38: =I34+I36 -> 54.6 | J38: =J34+J36 -> 79.498659 | K38: =K34+K36 -> 55.010888 | ... Q38: =Q34+Q36 -> 79.207901
C39: Earnings of Discontinued Ops. | D39: 0 | E39: 0 | F39: 0 | G39: 0 | H39: 0 | I39: 0 | J39: 0 | K39: =J39 -> 0 | L39: =K39 -> 0 | M39: =L39 -> 0 | N39: =M39 -> 0 | O39: =N39 -> 0 | P39: =O39 -> 0 | Q39: =P39 -> 0
C40: Net Income | D40: =D38 -> -1694.1 | E40: =E38 -> -1221.5 | F40: =F38 -> -80.7 | G40: =G38 -> 49.1 | H40: =H38 -> -109.6 | I40: =I38 -> 54.6 | J40: =J38 -> 79.498659 | K40: =K38 -> 55.010888 | ... Q40: =Q38 -> 79.207901
C41: Net Income Margin | D41: =D40/D$5 -> -1.0068347 | E41: =E40/E$5 -> -0.87493733 | F41: =F40/F$5 -> -0.062782013 | G41: =G40/G$5 -> 0.027536313 | H41: =H40/H$5 -> -0.067070559 | I41: =I40/I$5 -> 0.03557235 | J41: =J40/J$5 -> 0.069386602 | K41: =K40/K$5 -> 0.055206872 | ... Q41: =Q40/Q$5 -> 0.089422913
C43: Cap IQ Net Income | D43: -1694.1 | E43: -1221.5 | F43: -80.7 | G43: 49.1 | H43: -109.6 | I43: 54.6
C44: Net Income | D44: =D40 -> -1694.1 | E44: =E40 -> -1221.5 | F44: =F40 -> -80.7 | G44: =G40 -> 49.1 | H44: =H40 -> -109.6 | I44: =I40 -> 54.6
C45: Check | D45: =D43-D44 -> 0 | E45: =E43-E44 -> 0 | F45: =F43-F44 -> -1.563194e-13 | G45: =G43-G44 -> 0 | H45: =H43-H44 -> 0 | I45: =I43-I44 -> -7.8159701e-14
C46: EBIT | D46: =D18 -> 582.4 | E46: =E18 -> 276.9 | F46: =F18 -> 468.5 | G46: =G18 -> 545.9 | H46: =H18 -> 719.8 | I46: =I18 -> 548.9 | J46: =J18 -> 286.08387 | K46: =K18 -> 222.83169 | ... Q46: =Q18 -> 175.93538
C47: EBIT Margin | D47: =D46/D$5 -> 0.34613099 | E47: =E46/E$5 -> 0.19833823 | F47: =F46/F$5 -> 0.36447798 | G47: =G46/G$5 -> 0.30615221 | H47: =H46/H$5 -> 0.44048712 | I47: =I46/I$5 -> 0.35761287 | J47: =J46/J$5 -> 0.24969463 | K47: =K46/K$5 -> 0.22362556 | ... Q47: =Q46/Q$5 -> 0.1986248
C49: Depreciation & Amort. | D49: 724.6 | E49: 467.1 | F49: 378.9 | G49: 425.8 | H49: 436.6 | I49: 444.2 | J49: =J78 -> 354.29339 | K49: =K78 -> 308.13028 | L49: =L78 -> 310.35492 | M49: =M78 -> 304.92483 | N49: =N78 -> 299.28932 | O49: =O78 -> 293.44838 | P49: =P78 -> 283.81847 | Q49: =Q78 -> 273.90412
C50: Amortization of Intangibles | D50: 16.3 | E50: 13.1 | F50: 7.6 | G50: 6 | H50: 10.1 | I50: 11.4 | J50: =J80 -> 11.765894 | K50: =K80 -> 9.1354775 | L50: =L80 -> 7.8027433 | M50: =M80 -> 10.870798 | N50: =N80 -> 10.706372 | O50: =O80 -> 10.151356 | P50: =P80 -> 7.4221957 | Q50: =Q80 -> 6.3696527
...

Sheet BS
D1: 2019 | E1: =D1+1 -> 2020 | F1: =E1+1 -> 2021 | G1: =F1+1 -> 2022 | H1: =G1+1 -> 2023 | I1: =H1+1 -> 2024 | J1: =I1+1 -> 2025 | K1: =J1+1 -> 2026 | L1: =K1+1 -> 2027 | ... N1: =M1+1 -> 2029 | O1: =+N1+1 -> 2030 | P1: =+O1+1 -> 2031 | Q1: =+P1+1 -> 2032
C2: Tullow Oil Balance Sheet
C4: Balance Sheet
C5: Assets:
C6: Cash And Equivalents | D6: 288.8 | E6: 805.4 | F6: 469.1 | G6: 636.3 | H6: 499 | I6: 555.1 | J6: =+I6+CFS!J45 -> 388.58455 | K6: =+J6+CFS!K45 -> 374.62667 | L6: =+K6+CFS!L45 -> 526.2095 | M6: =+L6+CFS!M45 -> 824.84174 | N6: =+M6+CFS!N45 -> 1080.7474 | O6: =+N6+CFS!O45 -> 1306.872 | P6: =+O6+CFS!P45 -> 1479.0295 | Q6: =+P6+CFS!Q45 -> 1383.9009
C7: Total Cash & ST Investments | D7: =SUM(D6) -> 288.8 | E7: =SUM(E6) -> 805.4 | F7: =SUM(F6) -> 469.1 | G7: =SUM(G6) -> 636.3 | H7: =SUM(H6) -> 499 | I7: =SUM(I6) -> 555.1 | J7: =J6 -> 388.58455 | K7: =K6 -> 374.62667 | L7: =L6 -> 526.2095 | M7: =M6 -> 824.84174 | N7: =N6 -> 1080.7474 | O7: =O6 -> 1306.872 | P7: =P6 -> 1479.0295 | Q7: =Q6 -> 1383.9009
C9: Accounts Receivable | D9: 38.7 | E9: 79 | F9: 99.8 | G9: 26.8 | H9: 43.5 | I9: 137.9 | J9: =IS!J5/365*NWC!J20 -> 102.2179 | K9: =IS!K5/365*NWC!K20 -> 83.439286 | L9: =IS!L5/365*NWC!L20 -> 84.041699 | M9: =IS!M5/365*NWC!M20 -> 82.571273 | N9: =IS!N5/365*NWC!N20 -> 81.04522 | O9: =IS!O5/365*NWC!O20 -> 79.463541 | P9: =IS!P5/365*NWC!P20 -> 76.855834 | Q9: =IS!Q5/365*NWC!Q20 -> 74.171107
C10: Other Receivables | D10: 754.7 | E10: 558.3 | F10: 642.3 | G10: 467.7 | H10: 501.9 | I10: 357.1 | J10: =IS!J5/365*NWC!J22 -> 448.26347 | K10: =IS!K5/365*NWC!K22 -> 384.39641 | L10: =IS!L5/365*NWC!L22 -> 381.67225 | M10: =IS!M5/365*NWC!M22 -> 369.59116 | N10: =IS!N5/365*NWC!N22 -> 357.45717 | O10: =IS!O5/365*NWC!O22 -> 345.28119 | P10: =IS!P5/365*NWC!P22 -> 328.92111 | Q10: =IS!Q5/365*NWC!Q22 -> 312.57772
C11: Total Receivables | D11: =SUM(D9:D10) -> 793.4 | E11: =SUM(E9:E10) -> 637.3 | F11: =SUM(F9:F10) -> 742.1 | G11: =SUM(G9:G10) -> 494.5 | H11: =SUM(H9:H10) -> 545.4 | I11: =SUM(I9:I10) -> 495 | J11: =SUM(J9:J10) -> 550.48137 | K11: =SUM(K9:K10) -> 467.8357 | ... Q11: =SUM(Q9:Q10) -> 386.74883
C13: Inventory | D13: 191.5 | E13: 96.1 | F13: 134.8 | G13: 181.6 | H13: 107.3 | I13: 132.4 | J13: =IS!$J$8/365*-NWC!J24 -> 108.57666 | K13: =IS!K8/365*-NWC!K24 -> 94.429526 | L13: =IS!L8/365*-NWC!L24 -> 95.111286 | M13: =IS!M8/365*-NWC!M24 -> 93.447182 | N13: =IS!N8/365*-NWC!N24 -> 91.720125 | O13: =IS!O8/365*-NWC!O24 -> 89.930115 | P13: =IS!P8/365*-NWC!P24 -> 86.978933 | Q13: =IS!Q8/365*-NWC!Q24 -> 83.940585
C14: Prepaid Exp. | D14: 69.5 | E14: 60.7 | F14: 49.6 | G14: 31.3 | H14: 21.1 | I14: 17.1 | J14: =NWC!J26 -> 31.503395 | K14: =NWC!K26 -> 27.39862 | L14: =NWC!L26 -> 27.596432 | M14: =NWC!M26 -> 27.113594 | N14: =NWC!N26 -> 26.61249 | O14: =NWC!O26 -> 26.093121 | P14: =NWC!P26 -> 25.236839 | Q14: =NWC!Q26 -> 24.355266
C15: Other Current Assets | D15: 148.1 | E15: 307.3 | F15: 32.3 | G15: 84.3 | H15: 107.8 | I15: 24.7 | J15: =NWC!J29 -> 88.335898 | K15: =NWC!K29 -> 76.82606 | L15: =NWC!L29 -> 77.380727 | M15: =NWC!M29 -> 76.026843 | N15: =NWC!N29 -> 74.621743 | O15: =NWC!O29 -> 73.165424 | P15: =NWC!P29 -> 70.764399 | Q15: =NWC!Q29 -> 68.292457
C16: Total Current Assets | D16: =SUM(D13:D15)+D11+D7 -> 1491.3 | E16: =SUM(E13:E15)+E11+E7 -> 1906.8 | F16: =SUM(F13:F15)+F11+F7 -> 1427.9 | G16: =SUM(G13:G15)+G11+G7 -> 1428 | H16: =SUM(H13:H15)+H11+H7 -> 1280.6 | I16: =SUM(I13:I15)+I11+I7 -> 1224.3 | J16: =SUM(J13:J15)+J11+J7 -> 1167.4819 | K16: =SUM(K13:K15)+K11+K7 -> 1041.1166 | ... Q16: =SUM(Q13:Q15)+Q11+Q7 -> 1947.238
C18: Gross Property, Plant & Equipment | D18: 12508.7 | E18: 11548.4 | F18: 11682.9 | G18: 12409.4 | H18: 12572.8 | I18: 12661.6 | J18: =I18-CFS!J26+'Forecast Assumptions'!D89-'Forecast Assumptions'!D88 -> 12627.878 | K18: =J18-CFS!K26+'Forecast Assumptions'!E89-'Forecast Assumptions'!E88 -> 12745.078 | L18: =K18-CFS!L26+'Forecast Assumptions'!F89-'Forecast Assumptions'!F88 -> 12904.771 | M18: =L18-CFS!M26+'Forecast Assumptions'!G89-'Forecast Assumptions'!G88 -> 13059.327 | N18: =M18-CFS!N26+'Forecast Assumptions'!H89-'Forecast Assumptions'!H88 -> 13215.732 | O18: =N18-CFS!O26+'Forecast Assumptions'!I89-'Forecast Assumptions'!I88 -> 13373.688 | P18: =O18-CFS!P26+'Forecast Assumptions'!J89-'Forecast Assumptions'!J88 -> 13530.81 | Q18: =P18-CFS!Q26+'Forecast Assumptions'!K89-'Forecast Assumptions'!K88 -> 13686.618
C19: Accumulated Depreciation | D19: -8617 | E19: -8310.5 | F19: -8768.3 | G19: -9428 | H19: -10040 | I19: -10337.5 | J19: =I19-CFS!J10 -> -10953.505 | K19: =J19-CFS!K10 -> -11512.722 | L19: =K19-CFS!L10 -> -12052.411 | M19: =L19-CFS!M10 -> -12714.177 | N19: =M19-CFS!N10 -> -13318.257 | O19: =N19-CFS!O10 -> -13877.421 | P19: =O19-CFS!P10 -> -14366.243 | Q19: =P19-CFS!Q10 -> -14822.323
C20: Net Property, Plant & Equipment | D20: =SUM(D18:D19) -> 3891.7 | E20: =SUM(E18:E19) -> 3237.9 | F20: =SUM(F18:F19) -> 2914.6 | G20: =SUM(G18:G19) -> 2981.4 | H20: =SUM(H18:H19) -> 2532.8 | I20: =SUM(I18:I19) -> 2324.1 | J20: =SUM(J18:J19) -> 1674.373 | K20: =SUM(K18:K19) -> 1232.3558 | ... Q20: =SUM(Q18:Q19) -> -1135.7046
C22: Goodwill | D22: 0 | E22: 0 | F22: 0 | G22: 0 | H22: 0 | I22: 44.9 | J22: =I22 -> 44.9 | K22: =J22 -> 44.9 | L22: =K22 -> 44.9 | M22: =L22 -> 44.9 | N22: =M22 -> 44.9 | O22: =N22 -> 44.9 | P22: =O22 -> 44.9 | Q22: =P22 -> 44.9
C23: Other Intangibles | D23: 1764.4 | E23: 368.2 | F23: 354.6 | G23: 288.6 | H23: 287 | I23: 109.1 | J23: =I23 -> 109.1 | K23: =J23 -> 109.1 | L23: =K23 -> 109.1 | M23: =L23 -> 109.1 | N23: =M23 -> 109.1 | O23: =N23 -> 109.1 | P23: =O23 -> 109.1 | Q23: =P23 -> 109.1
C24: Deferred Tax Assets, LT | D24: 517.5 | E24: 494.3 | F24: 354.4 | G24: 14.5 | H24: 19.6 | I24: 8.3 | J24: =I24 -> 8.3 | K24: =J24 -> 8.3 | L24: =K24 -> 8.3 | M24: =L24 -> 8.3 | N24: =M24 -> 8.3 | O24: =N24 -> 8.3 | P24: =O24 -> 8.3 | Q24: =P24 -> 8.3
C25: Other Long-Term Assets | D25: 626.3 | E25: 550 | F25: 489.1 | G25: 327.1 | H25: 338.6 | I25: 340.8 | J25: =I25 -> 340.8 | K25: =J25 -> 340.8 | L25: =K25 -> 340.8 | M25: =L25 -> 340.8 | N25: =M25 -> 340.8 | O25: =N25 -> 340.8 | P25: =O25 -> 340.8 | Q25: =P25 -> 340.8
C26: Total Assets | D26: =SUM(D22:D25)+D20+D16 -> 8291.2 | E26: =SUM(E22:E25)+E20+E16 -> 6557.2 | F26: =SUM(F22:F25)+F20+F16 -> 5540.6 | G26: =SUM(G22:G25)+G20+G16 -> 5039.6 | H26: =SUM(H22:H25)+H20+H16 -> 4458.6 | I26: =SUM(I22:I25)+I20+I16 -> 4051.5 | J26: =SUM(J22:J25)+J20+J16 -> 3344.9549 | K26: =SUM(K22:K25)+K20+K16 -> 2776.5723 | ... Q26: =SUM(Q22:Q25)+Q20+Q16 -> 1314.6334
C28: Liabilities:
C29: Accounts Payable | D29: 95.4 | E29: 38.3 | F29: 60.2 | G29: 68.4 | H29: 22.3 | I29: 75.7 | J29: =-IS!J8/365*NWC!J32 -> 46.260816 | K29: =-IS!K8/365*NWC!K32 -> 40.233204 | L29: =-IS!L8/365*NWC!L32 -> 40.523679 | M29: =-IS!M8/365*NWC!M32 -> 39.814661 | N29: =-IS!N8/365*NWC!N32 -> 39.078821 | O29: =-IS!O8/365*NWC!O32 -> 38.316158 | P29: =-IS!P8/365*NWC!P32 -> 37.05876 | Q29: =-IS!Q8/365*NWC!Q32 -> 35.764224
C30: Accrued Exp. | D30: 695.5 | E30: 418.3 | F30: 381.3 | G30: 379.2 | H30: 498.6 | I30: 373.8 | J30: =J61 -> 401.00725 | K30: =K61 -> 348.7575 | L30: =L61 -> 351.27545 | M30: =M61 -> 345.1294 | N30: =N61 -> 338.75084 | O30: =O61 -> 332.13978 | P30: =P61 -> 321.24015 | Q30: =Q61 -> 310.01859
C31: Short-term Borrowings | D31: 0 | E31: 0 | F31: 0 | G31: 0 | H31: 0 | I31: 0 | J31: ='Debt Schedule'!J18 -> 0 | K31: ='Debt Schedule'!K18 -> 0 | L31: ='Debt Schedule'!L18 -> 0 | M31: ='Debt Schedule'!M18 -> 0 | N31: ='Debt Schedule'!N18 -> 0 | O31: ='Debt Schedule'!O18 -> 0 | P31: ='Debt Schedule'!P18 -> 0 | Q31: ='Debt Schedule'!Q18 -> 0
C32: Curr. Port. of LT Debt | D32: 0 | E32: 3170.5 | F32: 100 | G32: 100 | H32: 100 | I32: 589.4 | J32: =ABS(SUM('Debt Schedule'!J38:J39,'Debt Schedule'!J28:J29,'Debt Schedule'!J48:J49)) -> 775.55066 | K32: =ABS(SUM('Debt Schedule'!K38:K39,'Debt Schedule'!K28:K29,'Debt Schedule'!K48:K49)) -> 351.02934 | L32: =ABS(SUM('Debt Schedule'!L38:L39,'Debt Schedule'!L28:L29,'Debt Schedule'!L48:L49)) -> 127.64 | M32: =ABS(SUM('Debt Schedule'!M38:M39,'Debt Schedule'!M28:M29,'Debt Schedule'!M48:M49)) -> 127.64 | N32: =ABS(SUM('Debt Schedule'!N38:N39,'Debt Schedule'!N28:N29,'Debt Schedule'!N48:N49)) -> 127.64 | O32: =ABS(SUM('Debt Schedule'!O38:O39,'Debt Schedule'!O28:O29,'Debt Schedule'!O48:O49)) -> 127.64 | P32: =ABS(SUM('Debt Schedule'!P38:P39,'Debt Schedule'!P28:P29,'Debt Schedule'!P48:P49)) -> 127.64 | Q32: =ABS(SUM('Debt Schedule'!Q38:Q39,'Debt Schedule'!Q28:Q29,'Debt Schedule'!Q48:Q49)) -> 382.92
C33: Curr. Port. of Leases | D33: 284.2 | E33: 240.8 | F33: 251.5 | G33: 251.2 | H33: 185.7 | I33: 151.9 | J33: ='Debt Schedule'!J59 -> 132.95654 | K33: ='Debt Schedule'!K59 -> 114.01309 | L33: ='Debt Schedule'!L59 -> 95.069628 | M33: ='Debt Schedule'!M59 -> 76.12617 | N33: ='Debt Schedule'!N59 -> 57.182713 | O33: ='Debt Schedule'!O59 -> 38.239255 | P33: ='Debt Schedule'!P59 -> 19.295798 | Q33: ='Debt Schedule'!Q59 -> 0.35234002
C34: Curr. Income Taxes Payable | D34: 159.6 | E34: 52.2 | F34: 115.1 | G34: 186 | H34: 230.5 | I34: 175.3 | J34: =+I34 -> 175.3 | K34: =+J34 -> 175.3 | L34: =+K34 -> 175.3 | M34: =+L34 -> 175.3 | N34: =+M34 -> 175.3 | O34: =+N34 -> 175.3 | P34: =+O34 -> 175.3 | Q34: =+P34 -> 175.3
C35: Other Current Liabilities | D35: 240.1 | E35: 488.2 | F35: 435.5 | G35: 336.5 | H35: 188.9 | I35: 171.3 | J35: =J64 -> 194.77495 | K35: =K64 -> 169.3965 | L35: =L64 -> 170.61951 | M35: =M64 -> 167.63428 | N35: =N64 -> 164.53612 | O35: =O64 -> 161.32504 | P35: =P64 -> 156.03093 | Q35: =Q64 -> 150.58046
C36: Total Current Liabilities | D36: =SUM(D29:D35) -> 1474.8 | E36: =SUM(E29:E35) -> 4408.3 | F36: =SUM(F29:F35) -> 1343.6 | G36: =SUM(G29:G35) -> 1321.3 | H36: =SUM(H29:H35) -> 1226 | I36: =SUM(I29:I35) -> 1537.4 | J36: =SUM(J29:J35) -> 1725.8502 | K36: =SUM(K29:K35) -> 1198.7296 | ... Q36: =SUM(Q29:Q35) -> 1054.9356
C38: Long-Term Debt | D38: 3071.7 | E38: 0 | F38: 2468.7 | G38: 2372.8 | H38: 1984.6 | I38: 1386.4 | J38: ='Debt Schedule'!J40+'Debt Schedule'!J30+'Debt Schedule'!J50-J32 -> 596.59869 | K38: ='Debt Schedule'!K40+'Debt Schedule'!K30+'Debt Schedule'!K50-K32 -> 670.09066 | L38: ='Debt Schedule'!L40+'Debt Schedule'!L30+'Debt Schedule'!L50-L32 -> 765.84 | M38: ='Debt Schedule'!M40+'Debt Schedule'!M30+'Debt Schedule'!M50-M32 -> 638.2 | N38: ='Debt Schedule'!N40+'Debt Schedule'!N30+'Debt Schedule'!N50-N32 -> 510.56 | O38: ='Debt Schedule'!O40+'Debt Schedule'!O30+'Debt Schedule'!O50-O32 -> 382.92 | P38: ='Debt Schedule'!P40+'Debt Schedule'!P30+'Debt Schedule'!P50-P32 -> 255.28 | Q38: ='Debt Schedule'!Q40+'Debt Schedule'!Q30+'Debt Schedule'!Q50-Q32 -> -382.92
C39: Long-Term Leases | D39: 1140.9 | E39: 975.7 | F39: 911.9 | G39: 732.9 | H39: 721 | I39: 581 | J39: ='Debt Schedule'!J71 -> 508.54346 | K39: ='Debt Schedule'!K71 -> 436.08691 | L39: ='Debt Schedule'!L71 -> 363.63037 | M39: ='Debt Schedule'!M71 -> 291.17383 | N39: ='Debt Schedule'!N71 -> 218.71729 | O39: ='Debt Schedule'!O71 -> 146.26074 | P39: ='Debt Schedule'!P71 -> 73.804202 | Q39: ='Debt Schedule'!Q71 -> 1.34766
C40: Def. Tax Liability, Non-Curr. | D40: 793.4 | E40: 673.3 | F40: 677.3 | G40: 551.5 | H40: 420.5 | I40: 413 | J40: =+I40 -> 413 | K40: =+J40 -> 413 | L40: =+K40 -> 413 | M40: =+L40 -> 413 | N40: =+M40 -> 413 | O40: =+N40 -> 413 | P40: =+O40 -> 413 | Q40: =+P40 -> 413
C41: Other Non-Current Liabilities | D41: 826.8 | E41: 709.9 | F41: 605.2 | G41: 520.6 | H41: 465.9 | I41: 406.4 | J41: =I41 -> 406.4 | K41: =J41 -> 406.4 | L41: =K41 -> 406.4 | M41: =L41 -> 406.4 | N41: =M41 -> 406.4 | O41: =N41 -> 406.4 | P41: =O41 -> 406.4 | Q41: =P41 -> 406.4
C42: Total Liabilities | D42: =SUM(D38:D41)+D36 -> 7307.6 | E42: =SUM(E38:E41)+E36 -> 6767.2 | F42: =SUM(F38:F41)+F36 -> 6006.7 | G42: =SUM(G38:G41)+G36 -> 5499.1 | H42: =SUM(H38:H41)+H36 -> 4818 | I42: =SUM(I38:I41)+I36 -> 4324.2 | J42: =SUM(J38:J41)+J36 -> 3650.3924 | K42: =SUM(K38:K41)+K36 -> 3124.3072 | ... Q42: =SUM(Q38:Q41)+Q36 -> 1492.7633
C44: Equity:
C45: Common Stock | D45: 210.9 | E45: 211.7 | F45: 214.2 | G45: 215.2 | H45: 216.7 | I45: 217.5 | J45: =I45 -> 217.5 | K45: =J45 -> 217.5 | L45: =K45 -> 217.5 | M45: =L45 -> 217.5 | N45: =M45 -> 217.5 | O45: =N45 -> 217.5 | P45: =O45 -> 217.5 | Q45: =P45 -> 217.5
C46: Additional Paid In Capital | D46: 1294.7 | E46: 1294.7 | F46: 1294.7 | G46: 1294.7 | H46: 1294.7 | I46: 1294.7 | J46: =I46 -> 1294.7 | K46: =J46 -> 1294.7 | L46: =K46 -> 1294.7 | M46: =L46 -> 1294.7 | N46: =M46 -> 1294.7 | O46: =N46 -> 1294.7 | P46: =O46 -> 1294.7 | Q46: =P46 -> 1294.7
C47: Retained Earnings | D47: -1070.6 | E47: -2272 | F47: -2295.2 | G47: -2241.3 | H47: -2346.4 | I47: -2285.7 | J47: =I47+IS!J40-'Debt Schedule'!J77 -> -2318.4374 | K47: =J47+IS!K40-'Debt Schedule'!K77 -> -2360.7349 | L47: =K47+IS!L40-'Debt Schedule'!L77 -> -2374.8266 | M47: =L47+IS!M40-'Debt Schedule'!M77 -> -2371.5764 | N47: =M47+IS!N40-'Debt Schedule'!N77 -> -2351.3866 | O47: =N47+IS!O40-'Debt Schedule'!O77 -> -2314.3693 | P47: =O47+IS!P40-'Debt Schedule'!P77 -> -2262.5962 | Q47: =P47+IS!Q40-'Debt Schedule'!Q77 -> -2191.1299
C48: Treasury Stock | D48: 0 | E48: 0 | F48: 0 | G48: 0 | H48: 0 | I48: 0 | J48: =I48 -> 0 | K48: =J48 -> 0 | L48: =K48 -> 0 | M48: =L48 -> 0 | N48: =M48 -> 0 | O48: =N48 -> 0 | P48: =O48 -> 0 | Q48: =P48 -> 0
...

Sheet CFS
D1: 2019 | E1: =D1+1 -> 2020 | F1: =E1+1 -> 2021 | G1: =F1+1 -> 2022 | H1: =G1+1 -> 2023 | I1: =H1+1 -> 2024 | J1: =I1+1 -> 2025 | K1: =J1+1 -> 2026 | L1: =K1+1 -> 2027 | ... N1: =M1+1 -> 2029 | O1: =+N1+1 -> 2030 | P1: =+O1+1 -> 2031 | Q1: =+P1+1 -> 2032
C2: Tullow Oil Cash Flow Statement
C4: Cash Flow Statement
C5: Change in Cash: Operations
C6: Net Income | D6: =IS!D40 -> -1694.1 | E6: =IS!E40 -> -1221.5 | F6: =IS!F40 -> -80.7 | G6: =IS!G40 -> 49.1 | H6: =IS!H40 -> -109.6 | I6: =IS!I40 -> 54.6 | J6: =IS!J40 -> 79.498659 | K6: =IS!K40 -> 55.010888 | ... Q6: =IS!Q40 -> 79.207901
C7: Depreciation & Amort. | D7: 724.6 | E7: 467.1 | F7: 378.9 | G7: 425.8 | H7: 436.6 | I7: 444.2 | J7: =IS!J78 -> 354.29339 | K7: =IS!K78 -> 308.13028 | L7: =IS!L78 -> 310.35492 | M7: =IS!M78 -> 304.92483 | N7: =IS!N78 -> 299.28932 | O7: =IS!O78 -> 293.44838 | P7: =IS!P78 -> 283.81847 | Q7: =IS!Q78 -> 273.90412
C8: Amort. of Goodwill and Intangibles | D8: 16.3 | E8: 13.1 | F8: 7.6 | G8: 6 | H8: 10.1 | I8: 11.4 | J8: =IS!J80 -> 11.765894 | K8: =IS!K80 -> 9.1354775 | L8: =IS!L80 -> 7.8027433 | M8: =IS!M80 -> 10.870798 | N8: =IS!N80 -> 10.706372 | O8: =IS!O80 -> 10.151356 | P8: =IS!P80 -> 7.4221957 | Q8: =IS!Q80 -> 6.3696527
C9: Impair. of Oil, Gas & Mineral Prop. | D9: 0 | E9: 250 | F9: 114.2 | G9: 496.4 | H9: 426.1 | I9: 200.8 | J9: =IS!J84 -> 249.9456 | K9: =IS!K84 -> 241.95129 | L9: =IS!L84 -> 221.53132 | M9: =IS!M84 -> 345.9708 | N9: =IS!N84 -> 294.08417 | O9: =IS!O84 -> 255.5645 | P9: =IS!P84 -> 197.58081 | Q9: =IS!Q84 -> 175.80625
C10: Depreciation & Amort., Total | D10: =SUM(D7:D9) -> 740.9 | E10: =SUM(E7:E9) -> 730.2 | F10: =SUM(F7:F9) -> 500.7 | G10: =SUM(G7:G9) -> 928.2 | H10: =SUM(H7:H9) -> 872.8 | I10: =SUM(I7:I9) -> 656.4 | J10: =SUM(J7:J9) -> 616.00489 | K10: =SUM(K7:K9) -> 559.21705 | ... Q10: =SUM(Q7:Q9) -> 456.08002
C12: (Gain) Loss From Sale Of Assets | D12: -6.6 | E12: 3.4 | F12: -120.3 | G12: -3.1 | H12: -0.2 | I12: 0 | J12: =-IS!J30 -> -142.43333 | K12: =-IS!K30 -> -3.6333333 | L12: =-IS!L30 -> 0 | M12: =-IS!M30 -> -0.72666667 | N12: =-IS!N30 -> -0.72666667 | O12: =-IS!O30 -> -0.72666667 | P12: =-IS!P30 -> -0.72666667 | Q12: =-IS!Q30 -> -0.72666667
C13: Asset Write-down & Restructuring Costs | D13: 2013.8 | E13: 1021.7 | F13: 49.2 | G13: 0.1 | H13: 9 | I13: -38.9
C14: Stock-Based Compensation | D14: 24.8 | E14: 20.9 | F14: 11.6 | G14: 5.8 | H14: 6 | I14: 6.9 | J14: 0 | K14: 0 | L14: 0 | M14: 0 | N14: 0 | O14: 0 | P14: 0 | Q14: 0
C15: Net Cash From Discontinued Ops. | D15: 0 | E15: 0 | F15: 0 | G15: 0 | H15: 0 | I15: 0 | J15: 0 | K15: =J15 -> 0 | L15: =K15 -> 0 | M15: =L15 -> 0 | N15: =M15 -> 0 | O15: =N15 -> 0 | P15: =O15 -> 0 | Q15: =P15 -> 0
C16: Other Operating Activities | D16: 126.6 | E16: 25.5 | F16: 478.7 | G16: 50.4 | H16: 9.2 | I16: 54 | J16: =+BS!J35-BS!I35 -> 23.47495 | K16: =+BS!K35-BS!J35 -> -25.37845 | L16: =+BS!L35-BS!K35 -> 1.2230055 | M16: =+BS!M35-BS!L35 -> -2.9852255 | N16: =+BS!N35-BS!M35 -> -3.0981565 | O16: =+BS!O35-BS!N35 -> -3.2110875 | P16: =+BS!P35-BS!O35 -> -5.294106 | Q16: =+BS!Q35-BS!P35 -> -5.450472
C17: Change in Acc. Receivable | D17: 241.4 | E17: 195.2 | F17: -17.9 | G17: 288.4 | H17: -36.3 | I17: 0.7 | J17: =BS!I11-BS!J11 -> -55.481365 | K17: =BS!J11-BS!K11 -> 82.64567 | L17: =BS!K11-BS!L11 -> 2.1217491 | M17: =BS!L11-BS!M11 -> 13.551513 | N17: =BS!M11-BS!N11 -> 13.660044 | O17: =BS!N11-BS!O11 -> 13.757654 | P17: =BS!O11-BS!P11 -> 18.967791 | Q17: =BS!P11-BS!Q11 -> 19.028119
C18: Change In Inventories | D18: -56.6 | E18: 85.1 | F18: -41.9 | G18: -48 | H18: 66.6 | I18: -25.1 | J18: =BS!I13-BS!J13 -> 23.82334 | K18: =BS!J13-BS!K13 -> 14.147134 | L18: =BS!K13-BS!L13 -> -0.68176042 | M18: =BS!L13-BS!M13 -> 1.6641042 | N18: =BS!M13-BS!N13 -> 1.7270572 | O18: =BS!N13-BS!O13 -> 1.7900102 | P18: =BS!O13-BS!P13 -> 2.9511821 | Q18: =BS!P13-BS!Q13 -> 3.0383478
C19: Change In Prepaid Expenses | J19: =+BS!I14-BS!J14 -> -14.403395 | K19: =+BS!J14-BS!K14 -> 4.1047749 | L19: =+BS!K14-BS!L14 -> -0.19781202 | M19: =+BS!L14-BS!M14 -> 0.48283795 | N19: =+BS!M14-BS!N14 -> 0.5011037 | O19: =+BS!N14-BS!O14 -> 0.51936945 | P19: =+BS!O14-BS!P14 -> 0.85628215 | Q19: =+BS!P14-BS!Q14 -> 0.88157318
C20: Change in Acc. Payable | D20: -131.5 | E20: -161.9 | F20: 7.5 | G20: -193.1 | H20: 58.7 | I20: 49.9 | J20: =BS!J29-BS!I29 -> -29.439184 | K20: =BS!K29-BS!J29 -> -6.0276119 | L20: =BS!L29-BS!K29 -> 0.29047489 | M20: =BS!M29-BS!L29 -> -0.70901812 | N20: =BS!N29-BS!M29 -> -0.73584025 | O20: =BS!O29-BS!N29 -> -0.76266239 | P20: =BS!P29-BS!O29 -> -1.2573982 | Q20: =BS!Q29-BS!P29 -> -1.2945365
C21: Change in Other Net Operating Assets | D21: 0 | E21: 0 | F21: 0 | G21: 0 | H21: 0 | I21: 0 | J21: =BS!I15-BS!J15 -> -63.635898 | K21: =BS!J15-BS!K15 -> 11.509838 | L21: =BS!K15-BS!L15 -> -0.55466727 | M21: =BS!L15-BS!M15 -> 1.3538834 | N21: =BS!M15-BS!N15 -> 1.4051008 | O21: =BS!N15-BS!O15 -> 1.4563182 | P21: =BS!O15-BS!P15 -> 2.4010254 | Q21: =BS!P15-BS!Q15 -> 2.4719418
C22: Change in Accrued Expenses | D22: 0 | E22: 0 | F22: 0 | G22: 0 | H22: 0 | I22: 0 | J22: =+BS!J30-BS!I30 -> 27.20725 | K22: =+BS!K30-BS!J30 -> -52.24975 | L22: =+BS!L30-BS!K30 -> 2.5179525 | M22: =+BS!M30-BS!L30 -> -6.1460525 | N22: =+BS!N30-BS!M30 -> -6.3785575 | O22: =+BS!O30-BS!N30 -> -6.6110625 | P22: =+BS!P30-BS!O30 -> -10.89963 | Q22: =+BS!Q30-BS!P30 -> -11.22156
C23: Cash from Ops. | D23: =SUM(D12:D22)+D10+D6 -> 1258.7 | E23: =SUM(E12:E22)+E10+E6 -> 698.6 | F23: =SUM(F12:F22)+F10+F6 -> 786.9 | G23: =SUM(G12:G22)+G10+G6 -> 1077.8 | H23: =SUM(H12:H22)+H10+H6 -> 876.2 | I23: =SUM(I12:I22)+I10+I6 -> 758.5 | J23: =SUM(J12:J22)+J10+J6 -> 464.61592 | K23: =SUM(K12:K22)+K10+K6 -> 639.34621 | ... Q23: =SUM(Q12:Q22)+Q10+Q6 -> 542.01467
C25: Change in Cash: Investing
C26: Capital Expenditure | D26: -261.5 | E26: -217.3 | F26: -150.4 | G26: -263.8 | H26: -262.3 | I26: -196.7 | J26: =-IS!J68 -> -170.8446 | K26: =-IS!K68 -> -153.56644 | L26: =-IS!L68 -> -159.69338 | M26: =-IS!M68 -> -161.82974 | N26: =-IS!N68 -> -163.67816 | O26: =-IS!O68 -> -165.22867 | P26: =-IS!P68 -> -164.3956 | Q26: =-IS!Q68 -> -163.08177
C27: Sale of Property, Plant, and Equipment | D27: 7 | E27: 513.4 | F27: 132.8 | G27: 68.1 | H27: 0.7 | I27: 0 | J27: 0 | K27: 0 | L27: 0 | M27: 0 | N27: 0 | O27: 0 | P27: 0 | Q27: 0
C28: Cash Acquisitions | D28: 0 | E28: 0 | F28: 0 | G28: -126.8 | H28: 0 | I28: -8.1 | J28: 0 | K28: 0 | L28: 0 | M28: 0 | N28: 0 | O28: 0 | P28: 0 | Q28: 0
C29: Divestitures | D29: 0 | E29: 0 | F29: 0 | G29: 0 | H29: 0 | I29: 0 | J29: =+'Forecast Assumptions'!D88 -> 347 | K29: =+'Forecast Assumptions'!E88 -> 40 | L29: =+'Forecast Assumptions'!F88 -> 0 | M29: =+'Forecast Assumptions'!G88 -> 8 | N29: =+'Forecast Assumptions'!H88 -> 8 | O29: =+'Forecast Assumptions'!I88 -> 8 | P29: =+'Forecast Assumptions'!J88 -> 8 | Q29: =+'Forecast Assumptions'!K88 -> 8
C30: Sale (Purchase) of Intangible assets | D30: -259.4 | E30: -213.6 | F30: -86.1 | G30: -42.6 | H30: -30.2 | I30: -27.8 | J30: 0 | K30: 0 | L30: 0 | M30: 0 | N30: 0 | O30: 0 | P30: 0 | Q30: 0
C31: Invest. in Marketable & Equity Securt. | D31: 0 | E31: 0 | F31: 0 | G31: 0 | H31: 0 | I31: 0 | J31: 0 | K31: 0 | L31: 0 | M31: 0 | N31: 0 | O31: 0 | P31: 0 | Q31: 0
C32: Net (Inc.) Dec. in Loans Originated/Sold | D32: 0 | E32: 0 | F32: 0 | G32: 0 | H32: 0 | I32: 0 | J32: 0 | K32: 0 | L32: 0 | M32: 0 | N32: 0 | O32: 0 | P32: 0 | Q32: 0
C33: Other Investing Activities | D33: 1.9 | E33: 1.8 | F33: 2 | G33: 8.9 | H33: 23.3 | I33: 19.5
C34: Cash from Investing | D34: =SUM(D26:D33) -> -512 | E34: =SUM(E26:E33) -> 84.3 | F34: =SUM(F26:F33) -> -101.7 | G34: =SUM(G26:G33) -> -356.2 | H34: =SUM(H26:H33) -> -268.5 | I34: =SUM(I26:I33) -> -213.1 | J34: =SUM(J26:J33) -> 176.1554 | K34: =SUM(K26:K33) -> -113.56644 | ... Q34: =SUM(Q26:Q33) -> -155.08177
C36: Change in Cash: Financing
C37: Net Debt Issued/Repaid | D37: -317.1 | E37: -73.2 | F37: -735.8 | G37: -303.8 | H37: -497.5 | I37: -269 | J37: =BS!J32-BS!I32+BS!J38-BS!I38 -> -603.65066 | K37: =BS!K32-BS!J32+BS!K38-BS!J38 -> -351.02934 | L37: =BS!L32-BS!K32+BS!L38-BS!K38 -> -127.64 | M37: =BS!M32-BS!L32+BS!M38-BS!L38 -> -127.64 | N37: =BS!N32-BS!M32+BS!N38-BS!M38 -> -127.64 | O37: =BS!O32-BS!N32+BS!O38-BS!N38 -> -127.64 | P37: =BS!P32-BS!O32+BS!P38-BS!O38 -> -127.64 | Q37: =BS!Q32-BS!P32+BS!Q38-BS!P38 -> -382.92
C38: Short-term Borrowings | D38: 0 | E38: =BS!E31-BS!D31 -> 0 | F38: =BS!F31-BS!E31 -> 0 | G38: =BS!G31-BS!F31 -> 0 | H38: =BS!H31-BS!G31 -> 0 | I38: =BS!I31-BS!H31 -> 0 | J38: =BS!J31-BS!I31 -> 0 | K38: =BS!K31-BS!J31 -> 0 | L38: =BS!L31-BS!K31 -> 0 | ... Q38: =BS!Q31-BS!P31 -> 0
C39: Common Dividends Paid | D39: -100.9 | E39: 0 | F39: 0 | G39: 0 | H39: 0 | I39: 0 | J39: =I39 -> 0 | K39: =J39 -> 0 | L39: =K39 -> 0 | M39: =L39 -> 0 | N39: =M39 -> 0 | O39: =N39 -> 0 | P39: =O39 -> 0 | Q39: =P39 -> 0
C40: Special Dividend Paid | D40: 0 | E40: 0 | F40: 0 | G40: 0 | H40: 0 | I40: 0 | J40: =I40 -> 0 | K40: =J40 -> 0 | L40: =K40 -> 0 | M40: =L40 -> 0 | N40: =M40 -> 0 | O40: =N40 -> 0 | P40: =O40 -> 0 | Q40: =P40 -> 0
C41: Other Financing Activities | D41: -215.4 | E41: -198.5 | F41: -291.5 | G41: -249 | H41: -245 | I41: -223.2 | J41: ='Debt Schedule'!J71-'Debt Schedule'!I71+'Debt Schedule'!J59-'Debt Schedule'!I59-'Debt Schedule'!J77 -> -203.6361 | K41: ='Debt Schedule'!K71-'Debt Schedule'!J71+'Debt Schedule'!K59-'Debt Schedule'!J59-'Debt Schedule'!K77 -> -188.70831 | L41: ='Debt Schedule'!L71-'Debt Schedule'!K71+'Debt Schedule'!L59-'Debt Schedule'!K59-'Debt Schedule'!L77 -> -173.78052 | M41: ='Debt Schedule'!M71-'Debt Schedule'!L71+'Debt Schedule'!M59-'Debt Schedule'!L59-'Debt Schedule'!M77 -> -158.85272 | N41: ='Debt Schedule'!N71-'Debt Schedule'!M71+'Debt Schedule'!N59-'Debt Schedule'!M59-'Debt Schedule'!N77 -> -143.92493 | O41: ='Debt Schedule'!O71-'Debt Schedule'!N71+'Debt Schedule'!O59-'Debt Schedule'!N59-'Debt Schedule'!O77 -> -128.99713 | P41: ='Debt Schedule'!P71-'Debt Schedule'!O71+'Debt Schedule'!P59-'Debt Schedule'!O59-'Debt Schedule'!P77 -> -114.06934 | Q41: ='Debt Schedule'!Q71-'Debt Schedule'!P71+'Debt Schedule'!Q59-'Debt Schedule'!P59-'Debt Schedule'!Q77 -> -99.141547
C42: Cash from Financing | D42: =D37+D39+D41+D38 -> -633.4 | E42: =E37+E39+E41+E38 -> -271.7 | F42: =F37+F39+F41+F38 -> -1027.3 | G42: =G37+G39+G41+G38 -> -552.8 | H42: =H37+H39+H41+H38 -> -742.5 | I42: =I37+I39+I41+I38 -> -492.2 | J42: =J37+J39+J41+J38 -> -807.28676 | K42: =K37+K39+K41+K38 -> -539.73765 | ... Q42: =Q37+Q39+Q41+Q38 -> -482.06155
C44: Foreign Exchange Rate Adj. | D44: -4.3 | E44: 5.4 | F44: 5.8 | G44: -1.6 | H44: -2.5 | I44: 2.9 | J44: 0 | K44: =J44 -> 0 | L44: =K44 -> 0 | M44: =L44 -> 0 | N44: =M44 -> 0 | O44: =N44 -> 0 | P44: =O44 -> 0 | Q44: =P44 -> 0
C45: Net Change in Cash | D45: =D23+D34+D42+D44 -> 109 | E45: =E23+E34+E42+E44 -> 516.6 | F45: =F23+F34+F42+F44 -> -336.3 | G45: =G23+G34+G42+G44 -> 167.2 | H45: =H23+H34+H42+H44 -> -137.3 | I45: =I23+I34+I42+I44 -> 56.1 | J45: =J23+J34+J42+J44 -> -166.51545 | K45: =K23+K34+K42+K44 -> -13.957884 | ... Q45: =Q23+Q34+Q42+Q44 -> -95.128652
...

Sheet NWC
D1: 2019 | E1: =D1+1 -> 2020 | F1: =E1+1 -> 2021 | G1: =F1+1 -> 2022 | H1: =G1+1 -> 2023 | I1: =H1+1 -> 2024 | J1: =I1+1 -> 2025 | K1: =J1+1 -> 2026 | L1: =K1+1 -> 2027 | ... N1: =M1+1 -> 2029 | O1: =+N1+1 -> 2030 | P1: =+O1+1 -> 2031 | Q1: =+P1+1 -> 2032
C2: Tullow Oil Net Working Capital
C4: Net Working Capital
C5: Net Working Capital:
C6: Accounts Receivable | D6: =BS!D9 -> 38.7 | E6: =BS!E9 -> 79 | F6: =BS!F9 -> 99.8 | G6: =BS!G9 -> 26.8 | H6: =BS!H9 -> 43.5 | I6: =BS!I9 -> 137.9 | J6: =BS!J9 -> 102.2179 | K6: =BS!K9 -> 83.439286 | ... Q6: =BS!Q9 -> 74.171107
C7: Other Receivables | D7: =BS!D10 -> 754.7 | E7: =BS!E10 -> 558.3 | F7: =BS!F10 -> 642.3 | G7: =BS!G10 -> 467.7 | H7: =BS!H10 -> 501.9 | I7: =BS!I10 -> 357.1 | J7: =BS!J10 -> 448.26347 | K7: =BS!K10 -> 384.39641 | ... Q7: =BS!Q10 -> 312.57772
C8: Inventory | D8: =BS!D13 -> 191.5 | E8: =BS!E13 -> 96.1 | F8: =BS!F13 -> 134.8 | G8: =BS!G13 -> 181.6 | H8: =BS!H13 -> 107.3 | I8: =BS!I13 -> 132.4 | J8: =BS!J13 -> 108.57666 | K8: =BS!K13 -> 94.429526 | ... Q8: =BS!Q13 -> 83.940585
C9: Prepaid Exp. | D9: =BS!D14 -> 69.5 | E9: =BS!E14 -> 60.7 | F9: =BS!F14 -> 49.6 | G9: =BS!G14 -> 31.3 | H9: =BS!H14 -> 21.1 | I9: =BS!I14 -> 17.1 | J9: =BS!J14 -> 31.503395 | K9: =BS!K14 -> 27.39862 | ... Q9: =BS!Q14 -> 24.355266
C10: Other Current Assets | D10: =BS!D15 -> 148.1 | E10: =BS!E15 -> 307.3 | F10: =BS!F15 -> 32.3 | G10: =BS!G15 -> 84.3 | H10: =BS!H15 -> 107.8 | I10: =BS!I15 -> 24.7 | J10: =BS!J15 -> 88.335898 | K10: =BS!K15 -> 76.82606 | ... Q10: =BS!Q15 -> 68.292457
C12: Accounts Payable | D12: =BS!D29 -> 95.4 | E12: =BS!E29 -> 38.3 | F12: =BS!F29 -> 60.2 | G12: =BS!G29 -> 68.4 | H12: =BS!H29 -> 22.3 | I12: =BS!I29 -> 75.7 | J12: =BS!J29 -> 46.260816 | K12: =BS!K29 -> 40.233204 | ... Q12: =BS!Q29 -> 35.764224
C13: Other Current Liabilities | D13: =BS!D35 -> 240.1 | E13: =BS!E35 -> 488.2 | F13: =BS!F35 -> 435.5 | G13: =BS!G35 -> 336.5 | H13: =BS!H35 -> 188.9 | I13: =BS!I35 -> 171.3 | J13: =BS!J35 -> 194.77495 | K13: =BS!K35 -> 169.3965 | ... Q13: =BS!Q35 -> 150.58046
C14: Total NWC | D14: =SUM(D6:D10)-SUM(D12:D13) -> 867 | E14: =SUM(E6:E10)-SUM(E12:E13) -> 574.9 | F14: =SUM(F6:F10)-SUM(F12:F13) -> 463.1 | G14: =SUM(G6:G10)-SUM(G12:G13) -> 386.8 | H14: =SUM(H6:H10)-SUM(H12:H13) -> 570.4 | I14: =SUM(I6:I10)-SUM(I12:I13) -> 422.2 | J14: =SUM(J6:J10)-SUM(J12:J13) -> 537.86155 | K14: =SUM(K6:K10)-SUM(K12:K13) -> 456.8602 | ... Q14: =SUM(Q6:Q10)-SUM(Q12:Q13) -> 376.99245
C15: NWC (% of Sales) | D15: =D14/IS!D5 -> 0.51527398 | E15: =E14/IS!E5 -> 0.41178999 | F15: =F14/IS!F5 -> 0.36027696 | G15: =G14/IS!G5 -> 0.21692558 | H15: =H14/IS!H5 -> 0.34906065 | I15: =I14/IS!I5 -> 0.27506678 | J15: =J14/IS!J5 -> 0.46944673 | K15: =K14/IS!K5 -> 0.45848783 | ... Q15: =Q14/IS!Q5 -> 0.42561112
C17: NWC Change | E17: =+E14-D14 -> -292.1 | F17: =+F14-E14 -> -111.8 | G17: =+G14-F14 -> -76.3 | H17: =+H14-G14 -> 183.6 | I17: =+I14-H14 -> -148.2 | J17: =+J14-I14 -> 115.66155 | K17: =+K14-J14 -> -81.001355 | L17: =+L14-K14 -> -2.2009898 | ... Q17: =+Q14-P14 -> -18.674973
C19: Account | D19: 2019 | E19: =D19+1 -> 2020 | F19: =E19+1 -> 2021 | G19: =F19+1 -> 2022 | H19: =G19+1 -> 2023 | I19: =H19+1 -> 2024 | J19: =I19+1 -> 2025 | K19: =J19+1 -> 2026 | L19: =K19+1 -> 2027 | ... Q19: =P19+1 -> 2032 | S19: 2025 Step | T19: Fwd. Step
C20: Days Sales Outstanding | D20: =(D6/IS!D5)*365 -> 8.3950434 | E20: =(E6/IS!E5)*365 -> 20.653965 | F20: =(F6/IS!F5)*365 -> 28.339038 | G20: =(G6/IS!G5)*365 -> 5.4859514 | H20: =(H6/IS!H5)*365 -> 9.7163576 | I20: =(I6/IS!I5)*365 -> 32.79269 | J20: =AVERAGE(D20:I20)+S20 -> 32.563841 | K20: =J20-T20 -> 30.563841 | L20: =K20 -> 30.563841 | M20: =L20 -> 30.563841 | N20: =M20 -> 30.563841 | O20: =N20 -> 30.563841 | P20: =O20 -> 30.563841 | Q20: =P20 -> 30.563841 | S20: 15 | T20: 2
C22: Days Other Sales Outstanding | D22: =D7/IS!D5*365 -> 163.71419 | E22: =E7/IS!E5*365 -> 145.9634 | F22: =F7/IS!F5*365 -> 182.38642 | G22: =G7/IS!G5*365 -> 95.73804 | H22: =H7/IS!H5*365 -> 112.10666 | I22: =I7/IS!I5*365 -> 84.918561 | J22: =AVERAGE(D22:I22)+S22 -> 142.80455 | K22: =J22-$T$22 -> 140.80455 | L22: =K22-$T$22 -> 138.80455 | M22: =L22-$T$22 -> 136.80455 | N22: =M22-$T$22 -> 134.80455 | O22: =N22-$T$22 -> 132.80455 | P22: =O22-$T$22 -> 130.80455 | Q22: =P22-$T$22 -> 128.80455 | S22: 12 | T22: 2
C24: Days Inventory Outstanding | D24: =-D8/IS!D8*365 -> 71.992481 | E24: =-E8/IS!E8*365 -> 35.302436 | F24: =-F8/IS!F8*365 -> 77.974643 | G24: =-G8/IS!G8*365 -> 97.076743 | H24: =-H8/IS!H8*365 -> 46.441954 | I24: =-I8/IS!I8*365 -> 62.549832 | J24: =AVERAGE(D24:I24) -> 65.223015 | K24: =J24 -> 65.223015 | L24: =K24 -> 65.223015 | M24: =L24 -> 65.223015 | N24: =M24 -> 65.223015 | O24: =N24 -> 65.223015 | P24: =O24 -> 65.223015 | Q24: =P24 -> 65.223015
C26: =C9 -> Prepaid Exp. | D26: =D9 -> 69.5 | E26: =E9 -> 60.7 | F26: =F9 -> 49.6 | G26: =G9 -> 31.3 | H26: =H9 -> 21.1 | I26: =I9 -> 17.1 | J26: =IS!J5*J27 -> 31.503395 | K26: =IS!K5*K27 -> 27.39862 | L26: =IS!L5*L27 -> 27.596432 | M26: =IS!M5*M27 -> 27.113594 | N26: =IS!N5*N27 -> 26.61249 | O26: =IS!O5*O27 -> 26.093121 | P26: =IS!P5*P27 -> 25.236839 | Q26: =IS!Q5*Q27 -> 24.355266
C27: (% of Revenue) | D27: =D26/IS!D5 -> 0.041305123 | E27: =E26/IS!E5 -> 0.043478261 | F27: =F26/IS!F5 -> 0.03858721 | G27: =G26/IS!G5 -> 0.017553699 | H27: =H26/IS!H5 -> 0.012912306 | I27: =I26/IS!I5 -> 0.011140791 | J27: =AVERAGE(D27:I27) -> 0.027496232 | K27: =J27 -> 0.027496232 | L27: =K27 -> 0.027496232 | M27: =L27 -> 0.027496232 | N27: =M27 -> 0.027496232 | O27: =N27 -> 0.027496232 | P27: =O27 -> 0.027496232 | Q27: =P27 -> 0.027496232
C29: =C10 -> Other Current Assets | D29: =D10 -> 148.1 | E29: =E10 -> 307.3 | F29: =F10 -> 32.3 | G29: =G10 -> 84.3 | H29: =H10 -> 107.8 | I29: =I10 -> 24.7 | J29: =IS!J5*J30 -> 88.335898 | K29: =IS!K5*K30 -> 76.82606 | L29: =IS!L5*L30 -> 77.380727 | M29: =IS!M5*M30 -> 76.026843 | N29: =IS!N5*N30 -> 74.621743 | O29: =IS!O5*O30 -> 73.165424 | P29: =IS!P5*P30 -> 70.764399 | Q29: =IS!Q5*Q30 -> 68.292457
C30: (% of Revenue) | D30: =D29/IS!D5 -> 0.088018543 | E30: =E29/IS!E5 -> 0.22011317 | F30: =F29/IS!F5 -> 0.025128365 | G30: =G29/IS!G5 -> 0.047277214 | H30: =H29/IS!H5 -> 0.065969035 | I30: =I29/IS!I5 -> 0.016092254 | J30: =AVERAGE(D30:I30) -> 0.077099764 | K30: =J30 -> 0.077099764 | L30: =K30 -> 0.077099764 | M30: =L30 -> 0.077099764 | N30: =M30 -> 0.077099764 | O30: =N30 -> 0.077099764 | P30: =O30 -> 0.077099764 | Q30: =P30 -> 0.077099764
C32: Days Payable Outstanding | D32: =-D12/IS!D8*365 -> 35.864662 | E32: =-E12/IS!E8*365 -> 14.069545 | F32: =-F12/IS!F8*365 -> 34.822504 | G32: =-G12/IS!G8*365 -> 36.564148 | H32: =-H12/IS!H8*365 -> 9.6519625 | I32: =-I12/IS!I8*365 -> 35.763008 | J32: =AVERAGE(D32:I32) -> 27.789305 | K32: =J32 -> 27.789305 | L32: =K32 -> 27.789305 | M32: =L32 -> 27.789305 | N32: =M32 -> 27.789305 | O32: =N32 -> 27.789305 | P32: =O32 -> 27.789305 | Q32: =P32 -> 27.789305
C34: Other Current Liabilities | D34: =D13 -> 240.1 | E34: =E13 -> 488.2 | F34: =F13 -> 435.5 | G34: =G13 -> 336.5 | H34: =H13 -> 188.9 | I34: =I13 -> 171.3 | J34: =IS!J5*J35 -> 238.1425 | K34: =IS!K5*K35 -> 207.11342 | L34: =IS!L5*L35 -> 208.60873 | M34: =IS!M5*M35 -> 204.95883 | N34: =IS!N5*N35 -> 201.17085 | O34: =IS!O5*O35 -> 197.2448 | P34: =IS!P5*P35 -> 190.77194 | Q34: =IS!Q5*Q35 -> 184.1079
C35: (% of Revenue) | D35: =D34/IS!D5 -> 0.14269583 | E35: =E34/IS!E5 -> 0.34968842 | F35: =F34/IS!F5 -> 0.33880504 | G35: =G34/IS!G5 -> 0.18871628 | H35: =H34/IS!H5 -> 0.1155988 | I35: =I34/IS!I5 -> 0.11160336 | J35: =AVERAGE(D35:I35) -> 0.20785129 | K35: =J35 -> 0.20785129 | L35: =K35 -> 0.20785129 | M35: =L35 -> 0.20785129 | N35: =M35 -> 0.20785129 | O35: =N35 -> 0.20785129 | P35: =O35 -> 0.20785129 | Q35: =P35 -> 0.20785129

Sheet Debt Schedule
I1: 2024 | J1: =I1+1 -> 2025 | K1: =J1+1 -> 2026 | L1: =K1+1 -> 2027 | M1: =L1+1 -> 2028 | N1: =M1+1 -> 2029 | O1: =N1+1 -> 2030 | P1: =O1+1 -> 2031 | Q1: =P1+1 -> 2032
C2: Tullow Oil Debt Schedule
U3: TRUE | V3: FALSE
C4: Debt Schedule | S4: Refinance SD to 2032 | U4: Need Capital
C5: Beginning cash | J5: =BS!I6 -> 555.1 | K5: =BS!J6 -> 388.58455 | L5: =BS!K6 -> 374.62667 | M5: =BS!L6 -> 526.2095 | N5: =BS!M6 -> 824.84174 | O5: =BS!N6 -> 1080.7474 | P5: =BS!O6 -> 1306.872 | Q5: =BS!P6 -> 1479.0295 | S5: TRUE | U5: =IF(SUM(J22:Q22)>0,"Yes","No") -> No
C6: Add: CF from operations | J6: =CFS!J23 -> 464.61592 | K6: =CFS!K23 -> 639.34621 | L6: =CFS!L23 -> 612.69672 | M6: =CFS!M23 -> 738.95471 | N6: =CFS!N23 -> 683.14873 | O6: =CFS!O23 -> 639.99046 | P6: =CFS!P23 -> 570.26241 | Q6: =CFS!Q23 -> 542.01467
C7: Add: CF from investing | J7: =CFS!J34 -> 176.1554 | K7: =CFS!K34 -> -113.56644 | L7: =CFS!L34 -> -159.69338 | M7: =CFS!M34 -> -153.82974 | N7: =CFS!N34 -> -155.67816 | O7: =CFS!O34 -> -157.22867 | P7: =CFS!P34 -> -156.3956 | Q7: =CFS!Q34 -> -155.08177
C8: Less: Mandatory repayments | J8: =J48+J28+J38 -> -655.23 | K8: =K48+K28+K38 -> -165.83 | L8: =L48+L28+L38 -> -127.64 | M8: =M48+M28+M38 -> -127.64 | N8: =N48+N28+N38 -> -127.64 | O8: =O48+O28+O38 -> -127.64 | P8: =P48+P28+P38 -> -127.64 | Q8: =Q48+Q28+Q38 -> -382.92
C9: Less: Minimum Cash Balance | J9: =-'Forecast Assumptions'!$D$7 -> -300 | K9: =-'Forecast Assumptions'!$D$7 -> -300 | L9: =-'Forecast Assumptions'!$D$7 -> -300 | M9: =-'Forecast Assumptions'!$D$7 -> -300 | N9: =-'Forecast Assumptions'!$D$7 -> -300 | O9: =-'Forecast Assumptions'!$D$7 -> -300 | P9: =-'Forecast Assumptions'!$D$7 -> -300 | Q9: =-'Forecast Assumptions'!$D$7 -> -300
C10: Cash Available for optional Repayment of Debt (CARD) | J10: =SUM(J5:J9) -> 240.64131 | K10: =SUM(K5:K9) -> 448.53432 | L10: =SUM(L5:L9) -> 399.99001 | M10: =SUM(M5:M9) -> 683.69447 | N10: =SUM(N5:N9) -> 924.67231 | O10: =SUM(O5:O9) -> 1135.8692 | P10: =SUM(P5:P9) -> 1293.0989 | Q10: =SUM(Q5:Q9) -> 1183.0424
C12: CARD for revolver | J12: =J10 -> 240.64131 | K12: =K10 -> 448.53432 | L12: =L10 -> 399.99001 | M12: =M10 -> 683.69447 | N12: =N10 -> 924.67231 | O12: =O10 -> 1135.8692 | P12: =P10 -> 1293.0989 | Q12: =Q10 -> 1183.0424
C14: Revolver
C15: Beginning balance | J15: =I18 -> 150 | K15: 0 | L15: =K15 -> 0 | M15: =L15 -> 0 | N15: =M15 -> 0 | O15: =N15 -> 0 | P15: =O15 -> 0 | Q15: =P15 -> 0
C16: Mandatory repayments | J16: =IF(J1='Maturity Schedule'!$I$8,-'Debt Schedule'!J15,-MIN('Debt Schedule'!J15,'Maturity Schedule'!J8*'Maturity Schedule'!E8)) -> -150 | K16: 0 | L16: =K16 -> 0 | M16: =L16 -> 0 | N16: =M16 -> 0 | O16: =N16 -> 0 | P16: =O16 -> 0 | Q16: =P16 -> 0
C17: Optional draw (repayment) | J17: =IF(J12>0,-MIN(J15+J16,J12*'Maturity Schedule'!$K$8),-'Debt Schedule'!J12) -> 0 | K17: 0 | L17: =K17 -> 0 | M17: =L17 -> 0 | N17: =M17 -> 0 | O17: =N17 -> 0 | P17: =O17 -> 0 | Q17: =P17 -> 0
C18: Ending balance | I18: ='Maturity Schedule'!E8 -> 150 | J18: =SUM(J15:J17) -> 0 | K18: 0 | L18: =K18 -> 0 | M18: =L18 -> 0 | N18: =M18 -> 0 | O18: =N18 -> 0 | P18: =O18 -> 0 | Q18: =P18 -> 0
C19: Cash interest rate | J19: ='Maturity Schedule'!$G$7 -> 0.1 | K19: 0 | L19: =K19 -> 0 | M19: =L19 -> 0 | N19: =M19 -> 0 | O19: =N19 -> 0 | P19: =O19 -> 0 | Q19: =P19 -> 0
C20: Cash interest paid | J20: =J19*AVERAGE(I18:J18) -> 7.5 | K20: 0 | L20: =K20 -> 0 | M20: =L20 -> 0 | N20: =M20 -> 0 | O20: =N20 -> 0 | P20: =O20 -> 0 | Q20: =P20 -> 0
C22: Amount that Needs to be Refinanced | J22: =IF($S$5=TRUE," ",IF(J12>=0,0,-J12)) | K22: =IF($S$5=TRUE," ",IF(K12>=0,0,-K12)) | L22: =IF($S$5=TRUE," ",IF(L12>=0,0,-L12)) | M22: =IF($S$5=TRUE," ",IF(M12>=0,0,-M12)) | N22: =IF($S$5=TRUE," ",IF(N12>=0,0,-N12)) | O22: =IF($S$5=TRUE," ",IF(O12>=0,0,-O12)) | P22: =IF($S$5=TRUE," ",IF(P12>=0,0,-P12)) | Q22: =IF($S$5=TRUE," ",IF(Q12>=0,0,-Q12))
C24: CARD for Secured Notes | J24: =IF(J12>0,J12+J17,0) -> 240.64131 | K24: =IF(K12>0,K12+K17,0) -> 448.53432 | L24: =IF(L12>0,L12+L17,0) -> 399.99001 | M24: =IF(M12>0,M12+M17,0) -> 683.69447 | N24: =IF(N12>0,N12+N17,0) -> 924.67231 | O24: =IF(O12>0,O12+O17,0) -> 1135.8692 | P24: =IF(P12>0,P12+P17,0) -> 1293.0989 | Q24: =IF(Q12>0,Q12+Q17,0) -> 1183.0424
C26: Secured Notes
C27: Beginning balance | J27: =I30 -> 381.9 | K27: =J30 -> 223.38934 | L27: =K30 -> 0 | M27: =L30 -> 0 | N27: =M30 -> 0 | O27: =N30 -> 0 | P27: =O30 -> 0 | Q27: =P30 -> 0
C28: Mandatory repayments | J28: =IF(J1='Maturity Schedule'!$I$10,-'Debt Schedule'!J27,-MIN('Debt Schedule'!J27,'Maturity Schedule'!$J$10*'Maturity Schedule'!$E$10)) -> -38.19 | K28: =IF(K1='Maturity Schedule'!$I$10,-'Debt Schedule'!K27,-MIN('Debt Schedule'!K27,'Maturity Schedule'!$J$10*'Maturity Schedule'!$E$10)) -> -38.19 | L28: =IF(L1='Maturity Schedule'!$I$10,-'Debt Schedule'!L27,-MIN('Debt Schedule'!L27,'Maturity Schedule'!$J$10*'Maturity Schedule'!$E$10)) -> 0 | M28: =IF(M1='Maturity Schedule'!$I$10,-'Debt Schedule'!M27,-MIN('Debt Schedule'!M27,'Maturity Schedule'!$J$10*'Maturity Schedule'!$E$10)) -> 0 | N28: =IF(N1='Maturity Schedule'!$I$10,-'Debt Schedule'!N27,-MIN('Debt Schedule'!N27,'Maturity Schedule'!$J$10*'Maturity Schedule'!$E$10)) -> 0 | O28: =IF(O1='Maturity Schedule'!$I$10,-'Debt Schedule'!O27,-MIN('Debt Schedule'!O27,'Maturity Schedule'!$J$10*'Maturity Schedule'!$E$10)) -> 0 | P28: =IF(P1='Maturity Schedule'!$I$10,-'Debt Schedule'!P27,-MIN('Debt Schedule'!P27,'Maturity Schedule'!$J$10*'Maturity Schedule'!$E$10)) -> 0 | Q28: =IF(Q1='Maturity Schedule'!$I$10,-'Debt Schedule'!Q27,-MIN('Debt Schedule'!Q27,'Maturity Schedule'!$J$10*'Maturity Schedule'!$E$10)) -> 0
C29: Optional draw (repayment) | J29: =IF(J24>0,-MIN(J27+J28,J24*'Maturity Schedule'!$K$10),-J24) -> -120.32066 | K29: =IF(K24>0,-MIN(K27+K28,K24*'Maturity Schedule'!$K$10),-K24) -> -185.19934 | L29: =IF(L24>0,-MIN(L27+L28,L24*'Maturity Schedule'!$K$10),-L24) -> 0 | M29: =IF(M24>0,-MIN(M27+M28,M24*'Maturity Schedule'!$K$10),-M24) -> 0 | N29: =IF(N24>0,-MIN(N27+N28,N24*'Maturity Schedule'!$K$10),-N24) -> 0 | O29: =IF(O24>0,-MIN(O27+O28,O24*'Maturity Schedule'!$K$10),-O24) -> 0 | P29: =IF(P24>0,-MIN(P27+P28,P24*'Maturity Schedule'!$K$10),-P24) -> 0 | Q29: =IF(Q24>0,-MIN(Q27+Q28,Q24*'Maturity Schedule'!$K$10),-Q24) -> 0
C30: Ending balance | I30: ='Maturity Schedule'!E10 -> 381.9 | J30: =SUM(J27:J29) -> 223.38934 | K30: =SUM(K27:K29) -> 0 | L30: =SUM(L27:L29) -> 0 | M30: =SUM(M27:M29) -> 0 | N30: =SUM(N27:N29) -> 0 | O30: =SUM(O27:O29) -> 0 | P30: =SUM(P27:P29) -> 0 | Q30: =SUM(Q27:Q29) -> 0
C31: Cash interest rate | J31: ='Maturity Schedule'!$G$10+'Maturity Schedule'!Q6 -> 0.1949 | K31: ='Maturity Schedule'!$G$10+'Maturity Schedule'!R6 -> 0.1889 | L31: ='Maturity Schedule'!$G$10+'Maturity Schedule'!S6 -> 0.1901 | M31: ='Maturity Schedule'!$G$10+'Maturity Schedule'!T6 -> 0.1915 | N31: ='Maturity Schedule'!$G$10+'Maturity Schedule'!U6 -> 0.1929 | O31: ='Maturity Schedule'!$G$10+'Maturity Schedule'!V6 -> 0.1946 | P31: ='Maturity Schedule'!$G$10+'Maturity Schedule'!W6 -> 0.1961 | Q31: ='Maturity Schedule'!$G$10+'Maturity Schedule'!X6 -> 0.1974
C32: Cash interest paid | J32: =J31*AVERAGE(I30:J30) -> 58.985447 | K32: =K31*AVERAGE(J30:K30) -> 21.099124 | L32: =L31*AVERAGE(K30:L30) -> 0 | M32: =M31*AVERAGE(L30:M30) -> 0 | N32: =N31*AVERAGE(M30:N30) -> 0 | O32: =O31*AVERAGE(N30:O30) -> 0 | P32: =P31*AVERAGE(O30:P30) -> 0 | Q32: =Q31*AVERAGE(P30:Q30) -> 0
C34: CARD for Senior Notes | J34: =IF(J24>0,J24+J29,0) -> 120.32066 | K34: =IF(K24>0,K24+K29,0) -> 263.33498 | L34: =IF(L24>0,L24+L29,0) -> 399.99001 | M34: =IF(M24>0,M24+M29,0) -> 683.69447 | N34: =IF(N24>0,N24+N29,0) -> 924.67231 | O34: =IF(O24>0,O24+O29,0) -> 1135.8692 | P34: =IF(P24>0,P24+P29,0) -> 1293.0989 | Q34: =IF(Q24>0,Q24+Q29,0) -> 1183.0424
C36: Senior Notes
C37: Beginning balance | J37: =I40 -> 489.4 | K37: =J40 -> 0 | L37: =K40 -> 0 | M37: =L40 -> 0 | N37: =M40 -> 0 | O37: =N40 -> 0 | P37: =O40 -> 0 | Q37: =P40 -> 0
C38: Mandatory repayments | J38: =IF(J1='Maturity Schedule'!$I$9,-'Debt Schedule'!J37,-MIN('Debt Schedule'!J37,'Maturity Schedule'!J9*'Maturity Schedule'!E9)) -> -489.4 | K38: =IF(K1='Maturity Schedule'!$I$9,-'Debt Schedule'!K37,-MIN('Debt Schedule'!K37,'Maturity Schedule'!K9*'Maturity Schedule'!F9)) -> 0 | L38: =IF(L1='Maturity Schedule'!$I$9,-'Debt Schedule'!L37,-MIN('Debt Schedule'!L37,'Maturity Schedule'!L9*'Maturity Schedule'!G9)) -> 0 | M38: =IF(M1='Maturity Schedule'!$I$9,-'Debt Schedule'!M37,-MIN('Debt Schedule'!M37,'Maturity Schedule'!M9*'Maturity Schedule'!H9)) -> 0 | N38: =IF(N1='Maturity Schedule'!$I$9,-'Debt Schedule'!N37,-MIN('Debt Schedule'!N37,'Maturity Schedule'!N9*'Maturity Schedule'!I9)) -> 0 | O38: =IF(O1='Maturity Schedule'!$I$9,-'Debt Schedule'!O37,-MIN('Debt Schedule'!O37,'Maturity Schedule'!O9*'Maturity Schedule'!J9)) -> 0 | P38: =IF(P1='Maturity Schedule'!$I$9,-'Debt Schedule'!P37,-MIN('Debt Schedule'!P37,'Maturity Schedule'!P9*'Maturity Schedule'!K9)) -> 0 | Q38: =IF(Q1='Maturity Schedule'!$I$9,-'Debt Schedule'!Q37,-MIN('Debt Schedule'!Q37,'Maturity Schedule'!Q9*'Maturity Schedule'!L9)) -> 0
C39: Optional draw (repayment) | J39: =IF(J34>0,-MIN(J37+J38,J34*'Maturity Schedule'!$K$9),-'Debt Schedule'!J34) -> 0 | K39: =IF(K34>0,-MIN(K37+K38,K34*'Maturity Schedule'!$K$9),-'Debt Schedule'!K34) -> 0 | L39: =IF(L34>0,-MIN(L37+L38,L34*'Maturity Schedule'!$K$9),-'Debt Schedule'!L34) -> 0 | M39: =IF(M34>0,-MIN(M37+M38,M34*'Maturity Schedule'!$K$9),-'Debt Schedule'!M34) -> 0 | N39: =IF(N34>0,-MIN(N37+N38,N34*'Maturity Schedule'!$K$9),-'Debt Schedule'!N34) -> 0 | O39: =IF(O34>0,-MIN(O37+O38,O34*'Maturity Schedule'!$K$9),-'Debt Schedule'!O34) -> 0 | P39: =IF(P34>0,-MIN(P37+P38,P34*'Maturity Schedule'!$K$9),-'Debt Schedule'!P34) -> 0 | Q39: =IF(Q34>0,-MIN(Q37+Q38,Q34*'Maturity Schedule'!$K$9),-'Debt Schedule'!Q34) -> 0
C40: Ending balance | I40: ='Maturity Schedule'!E9 -> 489.4 | J40: =SUM(J37:J39) -> 0 | K40: =SUM(K37:K39) -> 0 | L40: =SUM(L37:L39) -> 0 | M40: =SUM(M37:M39) -> 0 | N40: =SUM(N37:N39) -> 0 | O40: =SUM(O37:O39) -> 0 | P40: =SUM(P37:P39) -> 0 | Q40: =SUM(Q37:Q39) -> 0
C41: Cash interest rate | J41: ='Maturity Schedule'!$G$9 -> 0.07 | K41: ='Maturity Schedule'!$G$9 -> 0.07 | L41: ='Maturity Schedule'!$G$9 -> 0.07 | M41: ='Maturity Schedule'!$G$9 -> 0.07 | N41: ='Maturity Schedule'!$G$9 -> 0.07 | O41: ='Maturity Schedule'!$G$9 -> 0.07 | P41: ='Maturity Schedule'!$G$9 -> 0.07 | Q41: ='Maturity Schedule'!$G$9 -> 0.07
C42: Cash interest paid | J42: =J41*AVERAGE(I40:J40) -> 17.129 | K42: =K41*AVERAGE(J40:K40) -> 0 | L42: =L41*AVERAGE(K40:L40) -> 0 | M42: =M41*AVERAGE(L40:M40) -> 0 | N42: =N41*AVERAGE(M40:N40) -> 0 | O42: =O41*AVERAGE(N40:O40) -> 0 | P42: =P41*AVERAGE(O40:P40) -> 0 | Q42: =Q41*AVERAGE(P40:Q40) -> 0
C44: CARD for Senior Notes | J44: =IF(J34>0,J34+J39,0) -> 120.32066 | K44: =IF(K34>0,K34+K39,0) -> 263.33498 | L44: =IF(L34>0,L34+L39,0) -> 399.99001 | M44: =IF(M34>0,M34+M39,0) -> 683.69447 | N44: =IF(N34>0,N34+N39,0) -> 924.67231 | O44: =IF(O34>0,O34+O39,0) -> 1135.8692 | P44: =IF(P34>0,P34+P39,0) -> 1293.0989 | Q44: =IF(Q34>0,Q34+Q39,0) -> 1183.0424
C46: Senior Notes
C47: Beginning balance | J47: =I50 -> 1276.4 | K47: =J50 -> 1148.76 | L47: =K50 -> 1021.12 | M47: =L50 -> 893.48 | N47: =M50 -> 765.84 | O47: =N50 -> 638.2 | P47: =O50 -> 510.56 | Q47: =P50 -> 382.92
C48: Mandatory repayments | J48: =IF(J1='Maturity Schedule'!$I$11,-'Debt Schedule'!J47,-MIN('Debt Schedule'!J47,'Maturity Schedule'!$J$11*'Maturity Schedule'!$E$11)) -> -127.64 | K48: =IF(K1='Maturity Schedule'!$I$11,-'Debt Schedule'!K47,-MIN('Debt Schedule'!K47,'Maturity Schedule'!$J$11*'Maturity Schedule'!$E$11)) -> -127.64 | L48: =IF(L1='Maturity Schedule'!$I$11,-'Debt Schedule'!L47,-MIN('Debt Schedule'!L47,'Maturity Schedule'!$J$11*'Maturity Schedule'!$E$11)) -> -127.64 | M48: =IF(M1='Maturity Schedule'!$I$11,-'Debt Schedule'!M47,-MIN('Debt Schedule'!M47,'Maturity Schedule'!$J$11*'Maturity Schedule'!$E$11)) -> -127.64 | N48: =IF(N1='Maturity Schedule'!$I$11,-'Debt Schedule'!N47,-MIN('Debt Schedule'!N47,'Maturity Schedule'!$J$11*'Maturity Schedule'!$E$11)) -> -127.64 | O48: =IF(O1='Maturity Schedule'!$I$11,-'Debt Schedule'!O47,-MIN('Debt Schedule'!O47,'Maturity Schedule'!$J$11*'Maturity Schedule'!$E$11)) -> -127.64 | P48: =IF(P1='Maturity Schedule'!$I$11,-'Debt Schedule'!P47,-MIN('Debt Schedule'!P47,'Maturity Schedule'!$J$11*'Maturity Schedule'!$E$11)) -> -127.64 | Q48: =IF(Q1='Maturity Schedule'!$I$11,-'Debt Schedule'!Q47,-MIN('Debt Schedule'!Q47,'Maturity Schedule'!$J$11*'Maturity Schedule'!$E$11)) -> -382.92
